<?xml version="1.0"?>
<!--
  DerpBot — simple two-wheeled differential drive robot.

  Layout (top view):

          front (+x)
             ↑
     ┌───────────────┐
     │               │  ← body: 0.30 × 0.20 × 0.10 m (L × W × H)
     │       ●       │  ← caster sphere r=0.02 at x=+0.13
     └───────────────┘
    ○               ○   ← wheels r=0.05, w=0.03, separation 0.23 m

  Coordinate convention:
    base_footprint  — at ground level (z=0), this is the spawn frame
    base_link       — at z=0.05 (wheel axle height), body centre
    left_wheel      — at (0, +0.115, 0) relative to base_link
    right_wheel     — at (0, -0.115, 0) relative to base_link
    caster_wheel    — at (0.13, 0, -0.03) relative to base_link → z=0.02 world

  Sensors: none (Phase 1 baseline).  LiDAR / camera added later.

  Gazebo plugins (Harmonic):
    gz-sim-diff-drive-system        — velocity control + odometry
    gz-sim-joint-state-publisher-system — joint state publication
-->
<robot name="derpbot">

  <!-- ═══════════════════════════ BASE STRUCTURE ════════════════════════════ -->

  <link name="base_footprint"/>

  <joint name="base_joint" type="fixed">
    <parent link="base_footprint"/>
    <child link="base_link"/>
    <origin xyz="0 0 0.05" rpy="0 0 0"/>
  </joint>

  <link name="base_link">
    <visual>
      <origin xyz="0 0 0.05" rpy="0 0 0"/>
      <geometry>
        <box size="0.30 0.20 0.10"/>
      </geometry>
      <material name="derpbot_blue">
        <color rgba="0.20 0.40 0.90 1.0"/>
      </material>
    </visual>
    <collision>
      <origin xyz="0 0 0.05" rpy="0 0 0"/>
      <geometry>
        <box size="0.30 0.20 0.10"/>
      </geometry>
    </collision>
    <inertial>
      <origin xyz="0 0 0.05" rpy="0 0 0"/>
      <mass value="1.5"/>
      <!-- Box inertia: m/12*(b²+c²), m/12*(a²+c²), m/12*(a²+b²) for a×b×c=0.30×0.20×0.10 -->
      <inertia ixx="0.00625" ixy="0.0" ixz="0.0"
               iyy="0.01250" iyz="0.0"
               izz="0.01625"/>
    </inertial>
  </link>

  <!-- ═══════════════════════════ LEFT WHEEL ════════════════════════════════ -->
  <!--  joint origin: (0, +0.115, 0) rel to base_link → wheel centre at z=0.05 world
        rpy=-pi/2 rotates cylinder so its rolling axis aligns with world-y              -->

  <joint name="left_wheel_joint" type="continuous">
    <parent link="base_link"/>
    <child link="left_wheel"/>
    <origin xyz="0 0.115 0" rpy="-1.5707963 0 0"/>
    <axis xyz="0 0 1"/>
  </joint>

  <link name="left_wheel">
    <visual>
      <geometry>
        <cylinder radius="0.05" length="0.03"/>
      </geometry>
      <material name="wheel_dark">
        <color rgba="0.15 0.15 0.15 1.0"/>
      </material>
    </visual>
    <collision>
      <geometry>
        <cylinder radius="0.05" length="0.03"/>
      </geometry>
    </collision>
    <inertial>
      <origin xyz="0 0 0" rpy="0 0 0"/>
      <mass value="0.2"/>
      <!-- Cylinder (axis=z in link frame): Ixx=Iyy=m/12*(3r²+h²), Izz=m/2*r²
           r=0.05, h=0.03: Ixx=0.2/12*(0.0075+0.0009)=0.000140, Izz=0.1*0.0025=0.000250 -->
      <inertia ixx="0.000140" ixy="0.0" ixz="0.0"
               iyy="0.000140" iyz="0.0"
               izz="0.000250"/>
    </inertial>
  </link>

  <!-- ══════════════════════════ RIGHT WHEEL ════════════════════════════════ -->

  <joint name="right_wheel_joint" type="continuous">
    <parent link="base_link"/>
    <child link="right_wheel"/>
    <origin xyz="0 -0.115 0" rpy="-1.5707963 0 0"/>
    <axis xyz="0 0 1"/>
  </joint>

  <link name="right_wheel">
    <visual>
      <geometry>
        <cylinder radius="0.05" length="0.03"/>
      </geometry>
      <material name="wheel_dark">
        <color rgba="0.15 0.15 0.15 1.0"/>
      </material>
    </visual>
    <collision>
      <geometry>
        <cylinder radius="0.05" length="0.03"/>
      </geometry>
    </collision>
    <inertial>
      <origin xyz="0 0 0" rpy="0 0 0"/>
      <mass value="0.2"/>
      <inertia ixx="0.000140" ixy="0.0" ixz="0.0"
               iyy="0.000140" iyz="0.0"
               izz="0.000250"/>
    </inertial>
  </link>

  <!-- ════════════════════════ CASTER WHEEL (front) ═════════════════════════ -->
  <!--  Sphere r=0.02.  Joint at (0.13, 0, -0.03) rel to base_link
        → sphere centre at z = 0.05 - 0.03 = 0.02 world (just touching ground). -->

  <joint name="caster_joint" type="fixed">
    <parent link="base_link"/>
    <child link="caster_wheel"/>
    <origin xyz="0.13 0 -0.03" rpy="0 0 0"/>
  </joint>

  <link name="caster_wheel">
    <visual>
      <geometry>
        <sphere radius="0.02"/>
      </geometry>
      <material name="caster_grey">
        <color rgba="0.50 0.50 0.50 1.0"/>
      </material>
    </visual>
    <collision>
      <geometry>
        <sphere radius="0.02"/>
      </geometry>
    </collision>
    <inertial>
      <origin xyz="0 0 0" rpy="0 0 0"/>
      <mass value="0.05"/>
      <!-- Solid sphere: I = 2/5*m*r² = 0.4*0.05*0.0004 = 0.000008 -->
      <inertia ixx="0.000008" ixy="0.0" ixz="0.0"
               iyy="0.000008" iyz="0.0"
               izz="0.000008"/>
    </inertial>
  </link>

  <!-- ════════════════════════ GAZEBO PLUGINS ═══════════════════════════════ -->

  <gazebo>
    <!-- Differential drive: subscribes cmd_vel, publishes odom + TF.
         ROBOT_NAME is a placeholder replaced at spawn time by spawn_robot.launch.py
         with the actual robot instance name (e.g. "derpbot_0").
         Using absolute Gazebo topic names (leading /) so ros_gz_bridge can use
         the same names on the ROS 2 side without any --remap gymnastics. -->
    <plugin filename="gz-sim-diff-drive-system"
            name="gz::sim::systems::DiffDrive">
      <left_joint>left_wheel_joint</left_joint>
      <right_joint>right_wheel_joint</right_joint>
      <wheel_separation>0.23</wheel_separation>
      <wheel_radius>0.05</wheel_radius>
      <odom_publish_frequency>20</odom_publish_frequency>
      <topic>/ROBOT_NAME/cmd_vel</topic>
      <odom_topic>/ROBOT_NAME/odom</odom_topic>
      <tf_topic>/ROBOT_NAME/tf</tf_topic>
      <!-- TF frame IDs: unprefixed (standard single-robot convention).
           For multi-robot, these would need per-instance prefixes too. -->
      <frame_id>odom</frame_id>
      <child_frame_id>base_footprint</child_frame_id>
      <max_linear_acceleration>1.0</max_linear_acceleration>
      <max_angular_acceleration>2.0</max_angular_acceleration>
    </plugin>

    <!-- Joint state publisher: publishes wheel angles for robot_state_publisher -->
    <plugin filename="gz-sim-joint-state-publisher-system"
            name="gz::sim::systems::JointStatePublisher">
      <topic>/ROBOT_NAME/joint_states</topic>
    </plugin>
  </gazebo>

  <!-- Frictionless caster so it doesn't resist turning -->
  <gazebo reference="caster_wheel">
    <mu1>0.0</mu1>
    <mu2>0.0</mu2>
    <kp>1000000.0</kp>
    <kd>100.0</kd>
  </gazebo>

  <!-- Drive wheels: good traction -->
  <gazebo reference="left_wheel">
    <mu1>1.0</mu1>
    <mu2>1.0</mu2>
    <kp>1000000.0</kp>
    <kd>1.0</kd>
  </gazebo>

  <gazebo reference="right_wheel">
    <mu1>1.0</mu1>
    <mu2>1.0</mu2>
    <kp>1000000.0</kp>
    <kd>1.0</kd>
  </gazebo>

</robot>
